<?xml version="1.0"?>
<robot xmlns:xacro="http://www.ros.org/wiki/xacro" name="arm_mada">

    <link name="arm_link">
        <visual>
        	<origin rpy="1.57075 0 0" xyz="0 0 0"/>
            <geometry>
                <cylinder radius="${arm_width}" length="${arm_bodylen}"/>
            </geometry>
            <material name="black"/>
        </visual>
        
    <collision>
      <origin rpy="1.57075 0 0" xyz="0 0 0"/>
      <geometry>
        <cylinder radius="${arm_width}" length="${arm_bodylen}"/>
      </geometry> 
    </collision>

    <inertial>
      <mass value="0.1"/>      
      <inertia ixx="6.0e-4" ixy="0" ixz="0" iyy="6.0e-4" iyz="0" izz="6.0e-4"/>
    </inertial>
    </link>
    
    <link name="forearm_link">
        <visual>
            	<origin rpy="1.57075 0 0" xyz="0 0.25 0"/>
            <geometry>
                <cylinder radius="${forearm_width}" length="${forearm_bodylen}"/>
            </geometry>
            <material name="white"/>
        </visual>
       
    <collision>
      <origin rpy="1.57075 0 0" xyz="0 0.25 0"/>
      <geometry>
        <cylinder radius="${forearm_width}" length="${forearm_bodylen}"/>
      </geometry> 
    </collision>

    <inertial>
      <mass value="0.09"/>
      <inertia ixx="6.0e-4" ixy="0" ixz="0" iyy="6.0e-4" iyz="0" izz="6.0e-4"/>
    </inertial>
    </link>
    
    <link name="hand_link">
        <visual>
            	<origin rpy="1.57075 0 3.14159" xyz="0 0.2 0"/>
            <geometry>
                <mesh filename="file://$(find mada_description)/mesh/hand.stl" scale="0.0017 0.0017 0.0017"/>
            </geometry>
            <material name="white"/>
        </visual>
       
    <collision>
      <origin rpy="1.57075 0 3.14159" xyz="0 0.2 0"/>
      <geometry>
        <mesh filename="file://$(find mada_description)/mesh/hand.stl" scale="0.001 0.001 0.001"/>
      </geometry> 
    </collision>

    <inertial>
      <mass value="0.05"/>
      <inertia ixx="6.0e-4" ixy="0" ixz="0" iyy="6.0e-4" iyz="0" izz="6.0e-4"/>
    </inertial>
    </link>
    
  <joint name="arm_joint" type="revolute">
    <parent link="arm_link"/>
    <child link="forearm_link"/>
    <origin xyz="0 0 0"/>
    <axis xyz="1 0 0"/>
    <limit effort="100" velocity="0.5" lower="-1.5708" upper="1.5708"/> 
  </joint>

  <joint name="hand_joint" type="revolute">
    <parent link="forearm_link"/>
    <child link="hand_link"/>
    <origin xyz="-0.045 0.2 -0.01"/>
    <axis xyz="0 1 0"/>
    <limit effort="100" velocity="0.5" lower="-1.5708" upper="1.5708"/> 
  </joint>
  
</robot>
