<?xml version="1.0"?>
<robot xmlns:xacro="http://www.ros.org/wiki/xacro" name="mada">

  <link name="base_link">
    <visual>
      <geometry>
        <cylinder length="${base_length}" radius="${base_radius}"/>
      </geometry>
      <material name="white"/>
    </visual>
    	
    <collision>
      <geometry>
        <cylinder length="${base_length}" radius="${base_radius}"/>
      </geometry> 
    </collision>

    <inertial>
      <mass value="0.18"/>
      <inertia ixx="6.0e-4" ixy="0" ixz="0" iyy="6.0e-4" iyz="0" izz="6.0e-4"/>
    </inertial>
  </link>

  <link name="neck_link">
    <visual>
      <geometry>
        <cylinder length="${neck_length}" radius="${neck_radius}"/>
      </geometry>
      <material name="white"/>
    </visual>
    
    <collision>
      <geometry>
        <cylinder length="${neck_length}" radius="${neck_radius}"/>
      </geometry> 
    </collision>

    <inertial>
      <mass value="0.18"/>
      <inertia ixx="6.0e-4" ixy="0" ixz="0" iyy="6.0e-4" iyz="0" izz="6.0e-4"/>
    </inertial>
    
  </link>

  <link name="head_link">
    <visual>
      <origin xyz="-0.45 0.2 0.05"/>
      <geometry>
        <mesh filename="file://$(find mada_description)/mesh/Bender_Keychain_Remix.stl" scale="0.02 0.02 0.02"/>/
      </geometry>
      <material name="white"/>
    </visual>

    <collision>
      <origin xyz="-0.45 0.2 0.05"/>
      <geometry>
        <mesh filename="file://$(find mada_description)/mesh/Bender_Keychain_Remix.stl" scale="0.02 0.02 0.02"/>
      </geometry> 
    </collision>

    <inertial>
      <mass value="0.18"/>
      <inertia ixx="6.0e-4" ixy="0" ixz="0" iyy="6.0e-4" iyz="0" izz="6.0e-4"/>
    </inertial>
  </link>
  
  <link name="base">
    <visual>
      <geometry>
        <box size="${base_size_x} ${base_size_y} ${base_size_z}"/>
      </geometry>
      <material name="black"/>
    </visual>
    
    <collision>
      <geometry>
        <box size="${base_size_x} ${base_size_y} ${base_size_z}"/>
      </geometry> 
    </collision>

    <inertial>
      <mass value="0.18"/>
      <inertia ixx="6.0e-4" ixy="0" ixz="0" iyy="6.0e-4" iyz="0" izz="6.0e-4"/>
    </inertial>
  </link>

  <link name="right_front_wheel">
    <visual>
      <origin rpy="1.57075 0 1.57075" xyz="0 0 0"/>
      <geometry>
        <cylinder length="${wheel_length}" radius="${wheel_radius}"/>
      </geometry>
      <material name="black"/>
    </visual>
    
    <collision>
      <origin rpy="1.57075 0 1.57075" xyz="0 0 0"/>
      <geometry>
        <cylinder length="${wheel_length}" radius="${wheel_radius}"/>
      </geometry> 
    </collision>

    <inertial>
      <mass value="0.18"/>
      <inertia ixx="6.0e-4" ixy="0" ixz="0" iyy="6.0e-4" iyz="0" izz="6.0e-4"/>
    </inertial>
  </link>

  <link name="right_back_wheel">
    <visual>
      <origin rpy="1.57075 0 1.57075" xyz="0 0 0"/>
      <geometry>
        <cylinder length="${wheel_length}" radius="${wheel_radius}"/>
      </geometry>
      <material name="black"/>
    </visual>
    
    <collision>
      <origin rpy="1.57075 0 1.57075" xyz="0 0 0"/>
      <geometry>
        <cylinder length="${wheel_length}" radius="${wheel_radius}"/>
      </geometry> 
    </collision>

    <inertial>
      <mass value="0.18"/>
      <inertia ixx="6.0e-4" ixy="0" ixz="0" iyy="6.0e-4" iyz="0" izz="6.0e-4"/>
    </inertial>
  </link>

  <link name="left_front_wheel">
    <visual>
      <origin rpy="1.57075 0 1.57075" xyz="0 0 0"/>
      <geometry>
        <cylinder length="${wheel_length}" radius="${wheel_radius}"/>
      </geometry>
      <material name="black"/>
    </visual>
    
    <collision>
      <origin rpy="1.57075 0 1.57075" xyz="0 0 0"/>
      <geometry>
        <cylinder length="${wheel_length}" radius="${wheel_radius}"/>
      </geometry> 
    </collision>

    <inertial>
      <mass value="0.18"/>
      <inertia ixx="6.0e-4" ixy="0" ixz="0" iyy="6.0e-4" iyz="0" izz="6.0e-4"/>
    </inertial>
  </link>

  <link name="left_back_wheel">
    <visual>
      <origin rpy="1.57075 0 1.57075" xyz="0 0 0"/>
      <geometry>
        <cylinder length="${wheel_length}" radius="${wheel_radius}"/>
      </geometry>
      <material name="black"/>
    </visual>
    
    <collision>
      <origin rpy="1.57075 0 1.57075" xyz="0 0 0"/>
      <geometry>
        <cylinder length="${wheel_length}" radius="${wheel_radius}"/>
      </geometry> 
    </collision>

    <inertial>
      <mass value="0.18"/>
      <inertia ixx="6.0e-4" ixy="0" ixz="0" iyy="6.0e-4" iyz="0" izz="6.0e-4"/>
    </inertial>
  </link>

  <joint name="neck_joint" type="fixed">
    <parent link="base_link"/>
    <child link="neck_link"/>
    <origin xyz="0 0 0.45"/>
  </joint>

  <joint name="head_joint" type="continuous">
    <parent link="neck_link"/>
    <child link="head_link"/>
    <origin xyz="0 0 0"/>
    <axis xyz="0 0 1" />
  </joint>

  <joint name="base_joint" type="fixed">
    <parent link="base_link"/>
    <child link="base"/>
    <origin xyz="0 0 -0.4"/>
  </joint>
  
  <joint name="left_back_wheel_joint" type="fixed">
    <parent link="base"/>
    <child link="left_back_wheel"/>
    <origin rpy="0 0 0" xyz="0.2 0.2 -0.1"/>
  </joint>

  <joint name="left_front_wheel_joint" type="continuous">
    <parent link="base"/>
    <child link="left_front_wheel"/>
    <origin rpy="0 0 0" xyz="0.2 -0.2 -0.1"/>
  </joint>
  
  <joint name="right_back_wheel_joint" type="fixed">
    <parent link="base"/>
    <child link="right_back_wheel"/>
    <origin rpy="0 0 0" xyz="-0.2 0.2 -0.1"/>
  </joint>
  
  <joint name="right_front_wheel_joint" type="continuous">
    <parent link="base"/>
    <child link="right_front_wheel"/>
    <origin rpy="0 0 0" xyz="-0.2 -0.2 -0.1"/>
  </joint>
</robot>
